<?xml version="1.0" encoding="UTF-8"?>
<testng-results skipped="0" failed="5" ignored="0" total="8" passed="3">
  <reporter-output>
  </reporter-output>
  <suite name="API Automation Sample Framework" duration-ms="5000" started-at="2021-05-26T19:23:59Z" finished-at="2021-05-26T19:24:04Z">
    <groups>
    </groups>
    <test name="Create Customer Test" duration-ms="3363" started-at="2021-05-26T19:23:59Z" finished-at="2021-05-26T19:24:02Z">
      <class name="testcases.CreateCustomerTest">
        <test-method status="FAIL" signature="validateCreateCustomerAPIWithInValidSecretKey(java.util.Hashtable)[pri:0, instance:testcases.CreateCustomerTest@7c1e2a9e]" name="validateCreateCustomerAPIWithInValidSecretKey" duration-ms="1958" started-at="2021-05-26T19:23:59Z" data-provider="data" finished-at="2021-05-26T19:24:01Z">
          <params>
            <param index="0">
              <value>
                <![CDATA[{email=java@way2automation.com, name=Rahul Arora, description=Adding the Second customer in framework}]]>
              </value>
            </param>
          </params>
          <exception class="java.lang.AssertionError">
            <message>
              <![CDATA[expected [200] but found [401]]]>
            </message>
            <full-stacktrace>
              <![CDATA[java.lang.AssertionError: expected [200] but found [401]
at org.testng.Assert.fail(Assert.java:96)
at org.testng.Assert.failNotEquals(Assert.java:776)
at org.testng.Assert.assertEqualsImpl(Assert.java:137)
at org.testng.Assert.assertEquals(Assert.java:118)
at org.testng.Assert.assertEquals(Assert.java:652)
at org.testng.Assert.assertEquals(Assert.java:662)
at testcases.CreateCustomerTest.validateCreateCustomerAPIWithInValidSecretKey(CreateCustomerTest.java:39)
at sun.reflect.NativeMethodAccessorImpl.invoke0(Native Method)
at sun.reflect.NativeMethodAccessorImpl.invoke(NativeMethodAccessorImpl.java:62)
at sun.reflect.DelegatingMethodAccessorImpl.invoke(DelegatingMethodAccessorImpl.java:43)
at java.lang.reflect.Method.invoke(Method.java:498)
at org.testng.internal.MethodInvocationHelper.invokeMethod(MethodInvocationHelper.java:124)
at org.testng.internal.Invoker.invokeMethod(Invoker.java:583)
at org.testng.internal.Invoker.invokeTestMethod(Invoker.java:719)
at org.testng.internal.TestMethodWithDataProviderMethodWorker.call(TestMethodWithDataProviderMethodWorker.java:71)
at org.testng.internal.TestMethodWithDataProviderMethodWorker.call(TestMethodWithDataProviderMethodWorker.java:14)
at java.util.concurrent.FutureTask.run(FutureTask.java:266)
at java.util.concurrent.Executors$RunnableAdapter.call(Executors.java:511)
at java.util.concurrent.FutureTask.run(FutureTask.java:266)
at java.util.concurrent.ThreadPoolExecutor.runWorker(ThreadPoolExecutor.java:1149)
at java.util.concurrent.ThreadPoolExecutor$Worker.run(ThreadPoolExecutor.java:624)
at java.lang.Thread.run(Thread.java:748)
]]>
            </full-stacktrace>
          </exception> <!-- java.lang.AssertionError -->
          <reporter-output>
          </reporter-output>
        </test-method> <!-- validateCreateCustomerAPIWithInValidSecretKey -->
        <test-method status="PASS" signature="validateCreateCustomerAPIWithValidSecretKey(java.util.Hashtable)[pri:0, instance:testcases.CreateCustomerTest@7c1e2a9e]" name="validateCreateCustomerAPIWithValidSecretKey" duration-ms="1365" started-at="2021-05-26T19:24:01Z" data-provider="data" finished-at="2021-05-26T19:24:02Z">
          <params>
            <param index="0">
              <value>
                <![CDATA[{email=def@gmail.com, name=EFGH, description=Adding the Third Customer in Framework}]]>
              </value>
            </param>
          </params>
          <reporter-output>
          </reporter-output>
        </test-method> <!-- validateCreateCustomerAPIWithValidSecretKey -->
        <test-method status="PASS" signature="validateCreateCustomerAPIWithValidSecretKey(java.util.Hashtable)[pri:0, instance:testcases.CreateCustomerTest@7c1e2a9e]" name="validateCreateCustomerAPIWithValidSecretKey" duration-ms="1365" started-at="2021-05-26T19:24:01Z" data-provider="data" finished-at="2021-05-26T19:24:02Z">
          <params>
            <param index="0">
              <value>
                <![CDATA[{email=abc@gmail.com, name=ABCD, description=Adding the Second customer in framework}]]>
              </value>
            </param>
          </params>
          <reporter-output>
          </reporter-output>
        </test-method> <!-- validateCreateCustomerAPIWithValidSecretKey -->
        <test-method status="PASS" signature="validateCreateCustomerAPIWithValidSecretKey(java.util.Hashtable)[pri:0, instance:testcases.CreateCustomerTest@7c1e2a9e]" name="validateCreateCustomerAPIWithValidSecretKey" duration-ms="1364" started-at="2021-05-26T19:24:01Z" data-provider="data" finished-at="2021-05-26T19:24:02Z">
          <params>
            <param index="0">
              <value>
                <![CDATA[{email=fgh@gmail.com, name=IJKL, description=Adding the forth Customer in framework}]]>
              </value>
            </param>
          </params>
          <reporter-output>
          </reporter-output>
        </test-method> <!-- validateCreateCustomerAPIWithValidSecretKey -->
      </class> <!-- testcases.CreateCustomerTest -->
    </test> <!-- Create Customer Test -->
    <test name="Delete Customer Test" duration-ms="1398" started-at="2021-05-26T19:24:03Z" finished-at="2021-05-26T19:24:04Z">
      <class name="testcases.DeleteCustomerTest">
        <test-method status="PASS" signature="setup()[pri:0, instance:testcases.DeleteCustomerTest@236e3f4e]" name="setup" is-config="true" duration-ms="323" started-at="2021-05-26T19:23:59Z" finished-at="2021-05-26T19:23:59Z">
          <reporter-output>
          </reporter-output>
        </test-method> <!-- setup -->
        <test-method status="FAIL" signature="deleteCustomer(java.util.Hashtable)[pri:0, instance:testcases.DeleteCustomerTest@236e3f4e]" name="deleteCustomer" duration-ms="1351" started-at="2021-05-26T19:24:03Z" data-provider="data" finished-at="2021-05-26T19:24:04Z">
          <params>
            <param index="0">
              <value>
                <![CDATA[{id=cus_JYT7Uo5CrRPPA5}]]>
              </value>
            </param>
          </params>
          <exception class="java.lang.AssertionError">
            <message>
              <![CDATA[expected [true] but found [false]]]>
            </message>
            <full-stacktrace>
              <![CDATA[java.lang.AssertionError: expected [true] but found [false]
at org.testng.Assert.fail(Assert.java:96)
at org.testng.Assert.failNotEquals(Assert.java:776)
at org.testng.Assert.assertTrue(Assert.java:44)
at org.testng.Assert.assertTrue(Assert.java:54)
at testcases.DeleteCustomerTest.deleteCustomer(DeleteCustomerTest.java:36)
at sun.reflect.NativeMethodAccessorImpl.invoke0(Native Method)
at sun.reflect.NativeMethodAccessorImpl.invoke(NativeMethodAccessorImpl.java:62)
at sun.reflect.DelegatingMethodAccessorImpl.invoke(DelegatingMethodAccessorImpl.java:43)
at java.lang.reflect.Method.invoke(Method.java:498)
at org.testng.internal.MethodInvocationHelper.invokeMethod(MethodInvocationHelper.java:124)
at org.testng.internal.Invoker.invokeMethod(Invoker.java:583)
at org.testng.internal.Invoker.invokeTestMethod(Invoker.java:719)
at org.testng.internal.TestMethodWithDataProviderMethodWorker.call(TestMethodWithDataProviderMethodWorker.java:71)
at org.testng.internal.TestMethodWithDataProviderMethodWorker.call(TestMethodWithDataProviderMethodWorker.java:14)
at java.util.concurrent.FutureTask.run(FutureTask.java:266)
at java.util.concurrent.Executors$RunnableAdapter.call(Executors.java:511)
at java.util.concurrent.FutureTask.run(FutureTask.java:266)
at java.util.concurrent.ThreadPoolExecutor.runWorker(ThreadPoolExecutor.java:1149)
at java.util.concurrent.ThreadPoolExecutor$Worker.run(ThreadPoolExecutor.java:624)
at java.lang.Thread.run(Thread.java:748)
]]>
            </full-stacktrace>
          </exception> <!-- java.lang.AssertionError -->
          <reporter-output>
          </reporter-output>
        </test-method> <!-- deleteCustomer -->
        <test-method status="FAIL" signature="deleteCustomer(java.util.Hashtable)[pri:0, instance:testcases.DeleteCustomerTest@236e3f4e]" name="deleteCustomer" duration-ms="1351" started-at="2021-05-26T19:24:03Z" data-provider="data" finished-at="2021-05-26T19:24:04Z">
          <params>
            <param index="0">
              <value>
                <![CDATA[{id=cus_JYTCXJTxlWDbv6}]]>
              </value>
            </param>
          </params>
          <exception class="java.lang.AssertionError">
            <message>
              <![CDATA[expected [true] but found [false]]]>
            </message>
            <full-stacktrace>
              <![CDATA[java.lang.AssertionError: expected [true] but found [false]
at org.testng.Assert.fail(Assert.java:96)
at org.testng.Assert.failNotEquals(Assert.java:776)
at org.testng.Assert.assertTrue(Assert.java:44)
at org.testng.Assert.assertTrue(Assert.java:54)
at testcases.DeleteCustomerTest.deleteCustomer(DeleteCustomerTest.java:36)
at sun.reflect.NativeMethodAccessorImpl.invoke0(Native Method)
at sun.reflect.NativeMethodAccessorImpl.invoke(NativeMethodAccessorImpl.java:62)
at sun.reflect.DelegatingMethodAccessorImpl.invoke(DelegatingMethodAccessorImpl.java:43)
at java.lang.reflect.Method.invoke(Method.java:498)
at org.testng.internal.MethodInvocationHelper.invokeMethod(MethodInvocationHelper.java:124)
at org.testng.internal.Invoker.invokeMethod(Invoker.java:583)
at org.testng.internal.Invoker.invokeTestMethod(Invoker.java:719)
at org.testng.internal.TestMethodWithDataProviderMethodWorker.call(TestMethodWithDataProviderMethodWorker.java:71)
at org.testng.internal.TestMethodWithDataProviderMethodWorker.call(TestMethodWithDataProviderMethodWorker.java:14)
at java.util.concurrent.FutureTask.run(FutureTask.java:266)
at java.util.concurrent.Executors$RunnableAdapter.call(Executors.java:511)
at java.util.concurrent.FutureTask.run(FutureTask.java:266)
at java.util.concurrent.ThreadPoolExecutor.runWorker(ThreadPoolExecutor.java:1149)
at java.util.concurrent.ThreadPoolExecutor$Worker.run(ThreadPoolExecutor.java:624)
at java.lang.Thread.run(Thread.java:748)
]]>
            </full-stacktrace>
          </exception> <!-- java.lang.AssertionError -->
          <reporter-output>
          </reporter-output>
        </test-method> <!-- deleteCustomer -->
        <test-method status="FAIL" signature="deleteCustomer(java.util.Hashtable)[pri:0, instance:testcases.DeleteCustomerTest@236e3f4e]" name="deleteCustomer" duration-ms="1350" started-at="2021-05-26T19:24:03Z" data-provider="data" finished-at="2021-05-26T19:24:04Z">
          <params>
            <param index="0">
              <value>
                <![CDATA[{id=cus_JYT75W0q60E5QE}]]>
              </value>
            </param>
          </params>
          <exception class="java.lang.AssertionError">
            <message>
              <![CDATA[expected [true] but found [false]]]>
            </message>
            <full-stacktrace>
              <![CDATA[java.lang.AssertionError: expected [true] but found [false]
at org.testng.Assert.fail(Assert.java:96)
at org.testng.Assert.failNotEquals(Assert.java:776)
at org.testng.Assert.assertTrue(Assert.java:44)
at org.testng.Assert.assertTrue(Assert.java:54)
at testcases.DeleteCustomerTest.deleteCustomer(DeleteCustomerTest.java:36)
at sun.reflect.NativeMethodAccessorImpl.invoke0(Native Method)
at sun.reflect.NativeMethodAccessorImpl.invoke(NativeMethodAccessorImpl.java:62)
at sun.reflect.DelegatingMethodAccessorImpl.invoke(DelegatingMethodAccessorImpl.java:43)
at java.lang.reflect.Method.invoke(Method.java:498)
at org.testng.internal.MethodInvocationHelper.invokeMethod(MethodInvocationHelper.java:124)
at org.testng.internal.Invoker.invokeMethod(Invoker.java:583)
at org.testng.internal.Invoker.invokeTestMethod(Invoker.java:719)
at org.testng.internal.TestMethodWithDataProviderMethodWorker.call(TestMethodWithDataProviderMethodWorker.java:71)
at org.testng.internal.TestMethodWithDataProviderMethodWorker.call(TestMethodWithDataProviderMethodWorker.java:14)
at java.util.concurrent.FutureTask.run(FutureTask.java:266)
at java.util.concurrent.Executors$RunnableAdapter.call(Executors.java:511)
at java.util.concurrent.FutureTask.run(FutureTask.java:266)
at java.util.concurrent.ThreadPoolExecutor.runWorker(ThreadPoolExecutor.java:1149)
at java.util.concurrent.ThreadPoolExecutor$Worker.run(ThreadPoolExecutor.java:624)
at java.lang.Thread.run(Thread.java:748)
]]>
            </full-stacktrace>
          </exception> <!-- java.lang.AssertionError -->
          <reporter-output>
          </reporter-output>
        </test-method> <!-- deleteCustomer -->
        <test-method status="FAIL" signature="deleteCustomer(java.util.Hashtable)[pri:0, instance:testcases.DeleteCustomerTest@236e3f4e]" name="deleteCustomer" duration-ms="1395" started-at="2021-05-26T19:24:03Z" data-provider="data" finished-at="2021-05-26T19:24:04Z">
          <params>
            <param index="0">
              <value>
                <![CDATA[{id=cus_JYTCnsRN5X6930}]]>
              </value>
            </param>
          </params>
          <exception class="java.lang.AssertionError">
            <message>
              <![CDATA[expected [true] but found [false]]]>
            </message>
            <full-stacktrace>
              <![CDATA[java.lang.AssertionError: expected [true] but found [false]
at org.testng.Assert.fail(Assert.java:96)
at org.testng.Assert.failNotEquals(Assert.java:776)
at org.testng.Assert.assertTrue(Assert.java:44)
at org.testng.Assert.assertTrue(Assert.java:54)
at testcases.DeleteCustomerTest.deleteCustomer(DeleteCustomerTest.java:36)
at sun.reflect.NativeMethodAccessorImpl.invoke0(Native Method)
at sun.reflect.NativeMethodAccessorImpl.invoke(NativeMethodAccessorImpl.java:62)
at sun.reflect.DelegatingMethodAccessorImpl.invoke(DelegatingMethodAccessorImpl.java:43)
at java.lang.reflect.Method.invoke(Method.java:498)
at org.testng.internal.MethodInvocationHelper.invokeMethod(MethodInvocationHelper.java:124)
at org.testng.internal.Invoker.invokeMethod(Invoker.java:583)
at org.testng.internal.Invoker.invokeTestMethod(Invoker.java:719)
at org.testng.internal.TestMethodWithDataProviderMethodWorker.call(TestMethodWithDataProviderMethodWorker.java:71)
at org.testng.internal.TestMethodWithDataProviderMethodWorker.call(TestMethodWithDataProviderMethodWorker.java:14)
at java.util.concurrent.FutureTask.run(FutureTask.java:266)
at java.util.concurrent.Executors$RunnableAdapter.call(Executors.java:511)
at java.util.concurrent.FutureTask.run(FutureTask.java:266)
at java.util.concurrent.ThreadPoolExecutor.runWorker(ThreadPoolExecutor.java:1149)
at java.util.concurrent.ThreadPoolExecutor$Worker.run(ThreadPoolExecutor.java:624)
at java.lang.Thread.run(Thread.java:748)
]]>
            </full-stacktrace>
          </exception> <!-- java.lang.AssertionError -->
          <reporter-output>
          </reporter-output>
        </test-method> <!-- deleteCustomer -->
        <test-method status="PASS" signature="teardown()[pri:0, instance:testcases.DeleteCustomerTest@236e3f4e]" name="teardown" is-config="true" duration-ms="0" started-at="2021-05-26T19:24:04Z" finished-at="2021-05-26T19:24:04Z">
          <reporter-output>
          </reporter-output>
        </test-method> <!-- teardown -->
      </class> <!-- testcases.DeleteCustomerTest -->
    </test> <!-- Delete Customer Test -->
  </suite> <!-- API Automation Sample Framework -->
</testng-results>
